<?xml version="1.0" ?>
<!-- =================================================================================== -->
<!-- |    This document was autogenerated by xacro from src/mas_industrial_robotics/mir_robots/mir_hardware_config/youbot-brsu-2/urdf/robot.urdf.xacro | -->
<!-- |    EDITING THIS FILE BY HAND IS NOT RECOMMENDED                                 | -->
<!-- =================================================================================== -->
<robot name="youbot" xmlns:controller="http://playerstage.sourceforge.net/gazebo/xmlschema/#controller" xmlns:interface="http://playerstage.sourceforge.net/gazebo/xmlschema/#interface" xmlns:sensor="http://playerstage.sourceforge.net/gazebo/xmlschema/#sensor">
  <material name="Grey2">
    <color rgba="0.9 0.9 0.9 1.0"/>
  </material>
  <material name="Caster">
    <texture filename="package://pr2_description/materials/textures/pr2_caster_texture.png"/>
  </material>
  <material name="Wheel_l">
    <texture filename="package://pr2_description/materials/textures/pr2_wheel_left.png"/>
  </material>
  <material name="Wheel_r">
    <texture filename="package://pr2_description/materials/textures/pr2_wheel_right.png"/>
  </material>
  <material name="RollLinks">
    <texture filename="package://pr2_description/materials/textures/pr2_wheel_left.png"/>
  </material>
  <!--<xacro:property name="link_0_mass" value="0.845" />
	<xacro:property name="link_1_mass" value="0.1" />
	<xacro:property name="link_2_mass" value="0.1" />
	<xacro:property name="link_3_mass" value="0.1" />
	<xacro:property name="link_4_mass" value="0.1" />
	<xacro:property name="link_5_mass" value="0.1" />-->
  <!-- TODO: add inertia tensor-->
  <gazebo>
    <plugin filename="libgazebo_ros_control.so" name="gazebo_ros_controller">
      <robotSimType>gazebo_ros_control/DefaultRobotHWSim</robotSimType>
      <legacyModeNS>true</legacyModeNS>
    </plugin>
  </gazebo>
  <material name="youBot/Orange">
    <color rgba="1.0 0.4 0.0 1.0"/>
  </material>
  <material name="youBot/Grey">
    <color rgba="0.7 0.7 0.7 1.0"/>
  </material>
  <material name="youBot/DarkGrey">
    <color rgba="0.3 0.3 0.3 1.0"/>
  </material>
  <material name="youBot/White">
    <color rgba="1.0 1.0 1.0 1.0"/>
  </material>
  <material name="youBot/Black">
    <color rgba="0.0 0.0 0.0 1.0"/>
  </material>
  <material name="youBot/Red">
    <color rgba="1.0 0.0 0.0 1.0"/>
  </material>
  <material name="youBot/Green">
    <color rgba="0.0 1.0 0.0 1.0"/>
  </material>
  <material name="youBot/Blue">
    <color rgba="0.0 0.0 0.8 1.0"/>
  </material>
  <material name="youBot/LightGrey">
    <color rgba="0.82 0.82 0.82 1.0"/>
  </material>
  <!-- Now we can start using the macros included above to define the actual youbot -->
  <link name="base_footprint"/>
  <joint name="base_footprint_joint" type="fixed">
    <origin rpy="0 0 0" xyz="0 0 0"/>
    <child link="base_link"/>
    <parent link="base_footprint"/>
  </joint>
  <link name="base_link">
    <inertial>
      <mass value="22.0"/>
      <origin xyz="0 0 0"/>
      <inertia ixx="5.652232699207" ixy="-0.009719934438" ixz="1.293988226423" iyy="5.669473158652" iyz="-0.007379583694" izz="3.683196351726"/>
    </inertial>
    <visual>
      <origin rpy="0 0 0" xyz="0 0 0"/>
      <geometry>
        <mesh filename="package://youbot_description/meshes/youbot_base/base.dae"/>
      </geometry>
      <material name="youBot/DarkGrey"/>
    </visual>
    <collision>
      <origin rpy="0 0 0" xyz="0 0 0"/>
      <geometry>
        <!--<box size="${base_size_x} ${base_size_y} ${base_size_z}" />-->
        <mesh filename="package://youbot_description/meshes/youbot_base/base_convex.dae"/>
      </geometry>
    </collision>
  </link>
  <!-- front left wheel -->
  <joint name="caster_joint_fl" type="continuous">
    <origin rpy="0 0 0" xyz="0.228 0.158 -0.034"/>
    <axis xyz="0 0 1"/>
    <limit effort="30" velocity="10"/>
    <dynamics damping="1.0" friction="1.0"/>
    <safety_controller k_velocity="10.0"/>
    <parent link="base_link"/>
    <child link="caster_link_fl"/>
  </joint>
  <link name="caster_link_fl">
    <inertial>
      <mass value="0.1"/>
      <origin xyz="0 0 0"/>
      <inertia ixx="0.012411765597" ixy="-0.000711733678" ixz="0.00050272983" iyy="0.015218160428" iyz="-0.000004273467" izz="0.011763977943"/>
    </inertial>
  </link>
  <joint name="wheel_joint_fl" type="continuous">
    <axis xyz="0 1 0"/>
    <limit effort="30" velocity="10"/>
    <origin rpy="0 0 0" xyz="0.0 0.0 0.0"/>
    <parent link="caster_link_fl"/>
    <dynamics damping="1.0" friction="1.0"/>
    <safety_controller k_velocity="10.0"/>
    <child link="wheel_link_fl"/>
  </joint>
  <link name="wheel_link_fl">
    <inertial>
      <mass value="1.4"/>
      <origin xyz="0 0 0"/>
      <inertia ixx="0.012411765597" ixy="-0.000711733678" ixz="0.00050272983" iyy="0.015218160428" iyz="-0.000004273467" izz="0.011763977943"/>
    </inertial>
    <visual>
      <origin rpy="0 0 0" xyz="0 0 0"/>
      <!--<mesh filename="package://youbot_description/meshes/youbot_base/youbot_wheel.stl" />-->
      <geometry>
        <sphere radius="0.0475"/>
      </geometry>
      <material name="youBot/Orange"/>
    </visual>
    <collision>
      <origin rpy="1.5707963267948966 0 0" xyz="0 0 0"/>
      <geometry>
        <cylinder length="0.0475" radius="0.0475"/>
      </geometry>
    </collision>
  </link>
  <!-- front right wheel -->
  <joint name="caster_joint_fr" type="continuous">
    <origin rpy="0 0 0" xyz="0.228 -0.158 -0.034"/>
    <axis xyz="0 0 1"/>
    <limit effort="30" velocity="10"/>
    <dynamics damping="1.0" friction="1.0"/>
    <safety_controller k_velocity="10.0"/>
    <parent link="base_link"/>
    <child link="caster_link_fr"/>
  </joint>
  <link name="caster_link_fr">
    <inertial>
      <mass value="0.1"/>
      <origin xyz="0 0 0"/>
      <inertia ixx="0.012411765597" ixy="-0.000711733678" ixz="0.00050272983" iyy="0.015218160428" iyz="-0.000004273467" izz="0.011763977943"/>
    </inertial>
  </link>
  <joint name="wheel_joint_fr" type="continuous">
    <axis xyz="0 1 0"/>
    <limit effort="30" velocity="10"/>
    <dynamics damping="1.0" friction="1.0"/>
    <safety_controller k_velocity="10.0"/>
    <origin rpy="0 0 0" xyz="0.0 0.0 0.0"/>
    <parent link="caster_link_fr"/>
    <child link="wheel_link_fr"/>
  </joint>
  <link name="wheel_link_fr">
    <inertial>
      <mass value="1.4"/>
      <origin xyz="0 0 0"/>
      <inertia ixx="0.012411765597" ixy="-0.000711733678" ixz="0.00050272983" iyy="0.015218160428" iyz="-0.000004273467" izz="0.011763977943"/>
    </inertial>
    <visual>
      <origin rpy="0 0 0" xyz="0 0 0"/>
      <geometry>
        <!--<mesh filename="package://youbot_description/meshes/youbot_base/youbot_wheel.stl" />-->
        <sphere radius="0.0475"/>
      </geometry>
      <material name="youBot/Orange"/>
    </visual>
    <collision>
      <origin rpy="1.5707963267948966 0 0" xyz="0 0 0"/>
      <geometry>
        <cylinder length="0.0475" radius="0.0475"/>
      </geometry>
    </collision>
  </link>
  <!-- back left wheel -->
  <joint name="caster_joint_bl" type="continuous">
    <origin rpy="0 0 0" xyz="-0.228 0.158 -0.034"/>
    <axis xyz="0 0 1"/>
    <limit effort="30" velocity="10"/>
    <dynamics damping="1.0" friction="1.0"/>
    <safety_controller k_velocity="10.0"/>
    <parent link="base_link"/>
    <child link="caster_link_bl"/>
  </joint>
  <link name="caster_link_bl">
    <inertial>
      <mass value="0.1"/>
      <origin xyz="0 0 0"/>
      <inertia ixx="0.012411765597" ixy="-0.000711733678" ixz="0.00050272983" iyy="0.015218160428" iyz="-0.000004273467" izz="0.011763977943"/>
    </inertial>
  </link>
  <joint name="wheel_joint_bl" type="continuous">
    <axis xyz="0 1 0"/>
    <limit effort="30" velocity="10"/>
    <dynamics damping="1.0" friction="1.0"/>
    <safety_controller k_velocity="10.0"/>
    <origin rpy="0 0 0" xyz="0.0 0.0 0.0"/>
    <parent link="caster_link_bl"/>
    <child link="wheel_link_bl"/>
  </joint>
  <link name="wheel_link_bl">
    <inertial>
      <mass value="1.4"/>
      <origin xyz="0 0 0"/>
      <inertia ixx="0.012411765597" ixy="-0.000711733678" ixz="0.00050272983" iyy="0.015218160428" iyz="-0.000004273467" izz="0.011763977943"/>
    </inertial>
    <visual>
      <origin rpy="0 0 0" xyz="0 0 0"/>
      <geometry>
        <!--<mesh filename="package://youbot_description/meshes/youbot_base/youbot_wheel.stl" />-->
        <sphere radius="0.0475"/>
      </geometry>
      <material name="youBot/Orange"/>
    </visual>
    <collision>
      <origin rpy="1.5707963267948966 0 0" xyz="0 0 0"/>
      <geometry>
        <cylinder length="0.0475" radius="0.0475"/>
      </geometry>
    </collision>
  </link>
  <!-- back right wheel -->
  <joint name="caster_joint_br" type="continuous">
    <origin rpy="0 0 0" xyz="-0.228 -0.158 -0.034"/>
    <axis xyz="0 0 1"/>
    <limit effort="30" velocity="10"/>
    <dynamics damping="1.0" friction="1.0"/>
    <safety_controller k_velocity="10.0"/>
    <parent link="base_link"/>
    <child link="caster_link_br"/>
  </joint>
  <link name="caster_link_br">
    <inertial>
      <mass value="0.1"/>
      <origin xyz="0 0 0"/>
      <inertia ixx="0.012411765597" ixy="-0.000711733678" ixz="0.00050272983" iyy="0.015218160428" iyz="-0.000004273467" izz="0.011763977943"/>
    </inertial>
  </link>
  <joint name="wheel_joint_br" type="continuous">
    <axis xyz="0 1 0"/>
    <limit effort="30" velocity="10"/>
    <dynamics damping="1.0" friction="1.0"/>
    <safety_controller k_velocity="10.0"/>
    <origin rpy="0 0 0" xyz="0.0 0.0 0.0"/>
    <parent link="caster_link_br"/>
    <child link="wheel_link_br"/>
  </joint>
  <link name="wheel_link_br">
    <inertial>
      <mass value="1.4"/>
      <origin xyz="0 0 0"/>
      <inertia ixx="0.012411765597" ixy="-0.000711733678" ixz="0.00050272983" iyy="0.015218160428" iyz="-0.000004273467" izz="0.011763977943"/>
    </inertial>
    <visual>
      <origin rpy="0 0 0" xyz="0 0 0"/>
      <geometry>
        <!--<mesh filename="package://youbot_description/meshes/youbot_base/youbot_wheel.stl" />-->
        <sphere radius="0.0475"/>
      </geometry>
      <material name="youBot/Orange"/>
    </visual>
    <collision>
      <origin rpy="1.5707963267948966 0 0" xyz="0 0 0"/>
      <geometry>
        <cylinder length="0.0475" radius="0.0475"/>
      </geometry>
    </collision>
  </link>
  <gazebo reference="youbot_base">
    </gazebo>
  <!-- front left wheel -->
  <gazebo reference="wheel_link_fl">
    <kp>1000000</kp>
    <kd>100</kd>
  </gazebo>
  <gazebo reference="caster_link_fl">
    </gazebo>
  <!-- front right wheel -->
  <gazebo reference="wheel_link_fr">
    <kp>1000000</kp>
    <kd>100</kd>
  </gazebo>
  <gazebo reference="caster_link_fr">   
    </gazebo>
  <!-- back left wheel -->
  <gazebo reference="wheel_link_bl">
    <kp>1000000</kp>
    <kd>100</kd>
  </gazebo>
  <gazebo reference="caster_link_bl">
    </gazebo>
  <!-- back right wheel -->
  <gazebo reference="wheel_link_br">
    <kp>1000000</kp>
    <kd>100</kd>
  </gazebo>
  <gazebo reference="caster_link_br">
    </gazebo>
  <!-- front left wheel -->
  <transmission name="wheel_trans_fl">
    <type>transmission_interface/SimpleTransmission</type>
    <actuator name="wheel_motor_fl">
      <mechanicalReduction>79.23809523809524</mechanicalReduction>
    </actuator>
    <joint name="wheel_joint_fl">
      <hardwareInterface>hardware_interface/VelocityJointInterface</hardwareInterface>
    </joint>
  </transmission>
  <transmission name="caster_trans_fl">
    <type>transmission_interface/SimpleTransmission</type>
    <actuator name="caster_motor_fl">
      <mechanicalReduction>79.23809523809524</mechanicalReduction>
    </actuator>
    <joint name="caster_joint_fl">
      <hardwareInterface>hardware_interface/VelocityJointInterface</hardwareInterface>
    </joint>
  </transmission>
  <!-- front right wheel -->
  <transmission name="wheel_trans_fr">
    <type>transmission_interface/SimpleTransmission</type>
    <actuator name="wheel_motor_fr">
      <mechanicalReduction>79.23809523809524</mechanicalReduction>
    </actuator>
    <joint name="wheel_joint_fr">
      <hardwareInterface>hardware_interface/VelocityJointInterface</hardwareInterface>
    </joint>
  </transmission>
  <transmission name="caster_trans_fr">
    <type>transmission_interface/SimpleTransmission</type>
    <actuator name="caster_motor_fr">
      <mechanicalReduction>79.23809523809524</mechanicalReduction>
    </actuator>
    <joint name="caster_joint_fr">
      <hardwareInterface>hardware_interface/VelocityJointInterface</hardwareInterface>
    </joint>
  </transmission>
  <!-- back left wheel -->
  <transmission name="wheel_trans_bl">
    <type>transmission_interface/SimpleTransmission</type>
    <actuator name="wheel_motor_bl">
      <mechanicalReduction>79.23809523809524</mechanicalReduction>
    </actuator>
    <joint name="wheel_joint_bl">
      <hardwareInterface>hardware_interface/VelocityJointInterface</hardwareInterface>
    </joint>
  </transmission>
  <transmission name="caster_trans_bl">
    <type>transmission_interface/SimpleTransmission</type>
    <actuator name="caster_motor_bl">
      <mechanicalReduction>79.23809523809524</mechanicalReduction>
    </actuator>
    <joint name="caster_joint_bl">
      <hardwareInterface>hardware_interface/VelocityJointInterface</hardwareInterface>
    </joint>
  </transmission>
  <!-- back right wheel -->
  <transmission name="wheel_trans_br">
    <type>transmission_interface/SimpleTransmission</type>
    <actuator name="wheel_motor_br">
      <mechanicalReduction>79.23809523809524</mechanicalReduction>
    </actuator>
    <joint name="wheel_joint_br">
      <hardwareInterface>hardware_interface/VelocityJointInterface</hardwareInterface>
    </joint>
  </transmission>
  <transmission name="caster_trans_br">
    <type>transmission_interface/SimpleTransmission</type>
    <actuator name="caster_motor_br">
      <mechanicalReduction>79.23809523809524</mechanicalReduction>
    </actuator>
    <joint name="caster_joint_br">
      <hardwareInterface>hardware_interface/VelocityJointInterface</hardwareInterface>
    </joint>
  </transmission>
  <material name="Silver">
    <color rgba="0.9 0.9 0.9 1.0"/>
  </material>
  <!-- joint between arm_7_link and sdh_palm_link -->
  <joint name="full_platform_joint" type="fixed">
    <origin rpy="0 0 0" xyz="0.0 0.0 0.07100000000000001"/>
    <parent link="base_link"/>
    <child link="full_platform_link"/>
  </joint>
  <link name="full_platform_link">
    <inertial>
      <origin rpy="0 0 0" xyz="-0.0 -0.0 0"/>
      <mass value="1.5"/>
      <inertia ixx="0.01" ixy="0" ixz="0" iyy="0.01" iyz="0" izz="0.01"/>
    </inertial>
    <visual>
      <origin rpy="0 0 0" xyz="-0.0 0.0 0"/>
      <geometry>
        <box size="0.6 0.396 0.005"/>
        <!--mesh filename="package://mir_description/meshes/misc/full_platform.dae"/-->
      </geometry>
      <material name="Silver"/>
    </visual>
    <collision>
      <origin rpy="0 0 0" xyz="-0.0 0.0 0"/>
      <geometry>
        <box size="0.6 0.396 0.005"/>
      </geometry>
    </collision>
  </link>
  <joint name="full_platform_arm_root" type="fixed">
    <origin rpy="0 0 -0.7853981633974483" xyz="0.20225 0.100 0"/>
    <parent link="full_platform_link"/>
    <child link="full_platform_arm_root_link"/>
  </joint>
  <link name="full_platform_arm_root_link"/>
  <!-- extensions -->
  <!-- joint between base_link and arm_0_link -->
  <joint name="arm_joint_0" type="fixed">
    <origin rpy="0 0 0" xyz="-0.022 0.0 0.037"/>
    <parent link="full_platform_arm_root_link"/>
    <child link="arm_link_0"/>
  </joint>
  <link name="arm_link_0">
    <inertial>
      <!--<origin xyz="0.023 0 0.006" rpy="0 0 0"/>-->
      <origin rpy="0 0 0" xyz="0 0 0"/>
      <mass value="0.961"/>
      <inertia ixx="0.01" ixy="0" ixz="0" iyy="0.01" iyz="0" izz="0.01"/>
    </inertial>
    <visual>
      <origin rpy="0 0 0" xyz="0 0 0"/>
      <geometry>
        <mesh filename="package://youbot_description/meshes/youbot_arm/arm0.dae"/>
      </geometry>
      <material name="youBot/DarkGrey"/>
    </visual>
    <collision>
      <!--<origin xyz="0.023 0 0.006" rpy="0 0 0"/>-->
      <origin rpy="0 0 0" xyz="0 0 0"/>
      <geometry>
        <mesh filename="package://youbot_description/meshes/youbot_arm/arm0_convex.dae"/>
        <!--<cylinder length="0.078" radius="0.093"/>-->
      </geometry>
    </collision>
  </link>
  <!-- joint between arm_0_link and arm_1_link -->
  <joint name="arm_joint_1" type="revolute">
    <origin rpy="3.141592653589793 0 0" xyz="0.024 0 0.115"/>
    <parent link="arm_link_0"/>
    <child link="arm_link_1"/>
    <axis xyz="0 0 1"/>
    <!--<calibration rising="${arm_1_ref}" falling="${arm_1_ref}"/>-->
    <dynamics damping="1" friction="0.5"/>
    <!-- damping - N*s/m, N*s*m/rad -->
    <!-- friction - N, N*m -->
    <limit effort="9.5" lower="-2.949606435870417" upper="2.949606435870417" velocity="1.5707963267948966"/>
    <!--effort - N, N*m-->
    <!--velocity - m/s, rad/s-->
    <!--safety_controller k_position="20" k_velocity="${9.5/M_PI / 2.0}" soft_lower_limit="${threshold}" soft_upper_limit="${joint_1_limit_soft}" /-->
    <!--k_position N/m, N/rad-->
    <!--k_velocity N*s/m, N*s*m/rad-->
    <!--for details: http://www.ros.org/wiki/pr2_controller_manager/safety_limits-->
  </joint>
  <link name="arm_link_1">
    <inertial>
      <mass value="1.39"/>
      <origin rpy="0 -0.3490658503988659 3.141592653589793" xyz="0.01516 0.00359 0.03105"/>
      <inertia ixx="0.0029525" ixy="0.0" ixz="0.0" iyy="0.0060091" iyz="0.0" izz="0.0058821"/>
    </inertial>
    <visual>
      <origin rpy="-3.141592653589793 0 0" xyz="0.0 0 0.02"/>
      <geometry>
        <mesh filename="package://youbot_description/meshes/youbot_arm/arm1.dae"/>
      </geometry>
      <material name="youBot/Orange"/>
    </visual>
    <collision>
      <origin rpy="-3.141592653589793 0 0" xyz="0.0 0 0.02"/>
      <geometry>
        <mesh filename="package://youbot_description/meshes/youbot_arm/arm1_convex.dae"/>
        <!--<cylinder length="0.102" radius="0.080"/>-->
      </geometry>
    </collision>
  </link>
  <!-- joint between arm_1_link and arm_2_link -->
  <joint name="arm_joint_2" type="revolute">
    <origin rpy="1.570796327 1.570796327 0" xyz="0.033 0 0.0"/>
    <parent link="arm_link_1"/>
    <child link="arm_link_2"/>
    <axis xyz="0 0 1"/>
    <!--<calibration rising="${arm_2_ref}" falling="${arm_2_ref}"/>-->
    <dynamics damping="1" friction="0.5"/>
    <limit effort="9.5" lower="-1.1344640137963142" upper="1.5707963267948966" velocity="1.5707963267948966"/>
    <!--safety_controller k_position="20" k_velocity="${2*9.5/M_PI}" soft_lower_limit="${threshold}" soft_upper_limit="${joint_2_limit_soft}" /-->
  </joint>
  <link name="arm_link_2">
    <inertial>
      <mass value="1.318"/>
      <origin rpy="-1.570796327 -1.570796327 0" xyz="0.11397 0.015 -0.019030000000000002"/>
      <inertia ixx="0.0031145" ixy="0.0" ixz="0.0" iyy="0.0005843" iyz="0.0" izz="0.0031631"/>
    </inertial>
    <visual>
      <origin rpy="1.570796327 0 1.570796327" xyz="0.078 0.0 -0.032"/>
      <geometry>
        <mesh filename="package://youbot_description/meshes/youbot_arm/arm2.dae"/>
      </geometry>
    </visual>
    <collision>
      <!--<origin xyz="0.001 -0.041 0.074" rpy="0 0 0" />-->
      <origin rpy="1.570796327 0 1.570796327" xyz="0.078 0.0 -0.032"/>
      <geometry>
        <mesh filename="package://youbot_description/meshes/youbot_arm/arm2_convex.dae"/>
        <!--<box size="0.074 0.082 0.222"/>-->
      </geometry>
    </collision>
  </link>
  <!-- joint between arm_2_link and arm_3_link -->
  <!--<joint name="${name}_joint_3" type="revolute">
			<origin xyz="0.000 0.000 0.155" rpy="0 ${146 * M_PI / 180} 0"/>
			<parent link="${name}_link_2"/>
			<child link="${name}_link_3"/>
			<axis xyz="0 1 0"/>
			<dynamics damping="1" friction="1" />
			<limit effort="${6}" velocity="${M_PI / 2.0}" lower="-${joint_3_limit}" upper="0"/>
      <safety_controller k_position="20" k_velocity="50" soft_lower_limit="-${joint_3_limit_soft}" soft_upper_limit="${threshold}" />
		</joint>-->
  <joint name="arm_joint_3" type="revolute">
    <origin rpy="0 0 -1.570796327" xyz="0.155 0.000 0.0"/>
    <parent link="arm_link_2"/>
    <child link="arm_link_3"/>
    <axis xyz="0 0 1"/>
    <dynamics damping="1" friction="0.5"/>
    <limit effort="6.0" lower="-2.6354471705114375" upper="2.548180707911721" velocity="1.5707963267948966"/>
    <!--safety_controller k_position="20" k_velocity="50" soft_lower_limit="-${joint_3_limit_soft}" soft_upper_limit="-${threshold}" /-->
  </joint>
  <link name="arm_link_3">
    <inertial>
      <mass value="0.821"/>
      <origin rpy="1.570796327 0 0" xyz="0.00013000000000000002 0.10441 0.02022"/>
      <inertia ixx="0.00172767" ixy="0.0" ixz="0.0" iyy="0.00041967" iyz="0.0" izz="0.0018468"/>
    </inertial>
    <visual>
      <origin rpy="-1.570796327 3.141592653589793 0" xyz="0.000 0.079 0.028"/>
      <geometry>
        <mesh filename="package://youbot_description/meshes/youbot_arm/arm3.dae"/>
      </geometry>
      <material name="youBot/Orange"/>
    </visual>
    <collision>
      <!--<origin xyz="0.000 0.025 0.067" rpy="0 0 0" />-->
      <origin rpy="-1.570796327 3.141592653589793 0" xyz="0.000 0.079 0.028"/>
      <geometry>
        <mesh filename="package://youbot_description/meshes/youbot_arm/arm3_convex.dae"/>
        <!--<box size="0.064 0.054 0.192"/>-->
      </geometry>
    </collision>
  </link>
  <!-- joint between arm_3_link and arm_4_link -->
  <joint name="arm_joint_4" type="revolute">
    <origin rpy="0 0 0" xyz="0.000 0.135 0.0"/>
    <parent link="arm_link_3"/>
    <child link="arm_link_4"/>
    <axis xyz="0 0 1"/>
    <!--<calibration rising="${arm_4_ref}" falling="${arm_4_ref}"/>-->
    <dynamics damping="1" friction="0.5"/>
    <limit effort="2.0" lower="-1.7889624832941877" upper="1.7889624832941877" velocity="1.5707963267948966"/>
    <!--safety_controller k_position="20" k_velocity="100" soft_lower_limit="0" soft_upper_limit="${joint_4_limit_soft}" /-->
  </joint>
  <link name="arm_link_4">
    <inertial>
      <mass value="0.769"/>
      <origin rpy="2.443460952792061 0 3.141592653589793" xyz="0.00015 0.05353 -0.024640000000000002"/>
      <inertia ixx="0.0006764" ixy="0.0" ixz="0.0" iyy="0.0010573" iyz="0.0" izz="0.0006610"/>
    </inertial>
    <visual>
      <!-- <origin xyz="0 -0.010 0.029" rpy="${M_PI} 0 0"/> -->
      <origin rpy="-1.570796327 3.141592653589793 0" xyz="0 0.029 -0.010"/>
      <geometry>
        <mesh filename="package://youbot_description/meshes/youbot_arm/arm4.dae"/>
      </geometry>
      <material name="youBot/Orange"/>
    </visual>
    <collision>
      <!--<origin xyz="0 0 0.026" rpy="0 0 0" />-->
      <origin rpy="-1.570796327 3.141592653589793 0" xyz="0 0.029 -0.010"/>
      <geometry>
        <mesh filename="package://youbot_description/meshes/youbot_arm/arm4_convex.dae"/>
        <!--<box size="0.058 0.100 0.118"/>-->
      </geometry>
    </collision>
  </link>
  <!-- joint between arm_4_link and arm_5_link -->
  <joint name="arm_joint_5" type="revolute">
    <origin rpy="-1.570796327 0 0" xyz="0.00 0.1136 0.0"/>
    <parent link="arm_link_4"/>
    <child link="arm_link_5"/>
    <axis xyz="0 0 -1"/>
    <!--<calibration rising="${arm_5_ref}" falling="${arm_5_ref}"/>-->
    <dynamics damping="0.5" friction="0.5"/>
    <limit effort="1.0" lower="-2.8797932657906435" upper="2.8797932657906435" velocity="1.5707963267948966"/>
    <!--safety_controller k_position="20" k_velocity="100" soft_lower_limit="0" soft_upper_limit="${joint_5_limit_soft}" /-->
  </joint>
  <link name="arm_link_5">
    <inertial>
      <mass value="0.387"/>
      <origin rpy="0 1.570796327 0" xyz="0.0 0.0012 -0.01648"/>
      <inertia ixx="0.0001934" ixy="0.0" ixz="0.0" iyy="0.0001602" iyz="0.0" izz="0.0000689"/>
    </inertial>
    <visual>
      <origin rpy="0 0 0" xyz="0.00 0 -0.019"/>
      <geometry>
        <mesh filename="package://youbot_description/meshes/youbot_arm/arm5.dae"/>
      </geometry>
      <material name="youBot/DarkGrey"/>
    </visual>
    <collision>
      <origin rpy="0 0 0" xyz="0.00 0 -0.019"/>
      <geometry>
        <mesh filename="package://youbot_description/meshes/youbot_arm/arm5_convex.dae"/>
        <!--<box size="0.054 0.096 0.030"/>-->
      </geometry>
    </collision>
  </link>
  <gazebo reference="arm_link_0">
    <turnGravityOff>false</turnGravityOff>
  </gazebo>
  <gazebo reference="arm_link_1">
    <turnGravityOff>false</turnGravityOff>
  </gazebo>
  <gazebo reference="arm_link_2">
    <turnGravityOff>false</turnGravityOff>
  </gazebo>
  <gazebo reference="arm_link_3">
    <turnGravityOff>false</turnGravityOff>
  </gazebo>
  <gazebo reference="arm_link_4">
    <turnGravityOff>false</turnGravityOff>
  </gazebo>
  <gazebo reference="arm_link_5">
    <turnGravityOff>false</turnGravityOff>
  </gazebo>
  <transmission name="arm_trans_1">
    <type>transmission_interface/SimpleTransmission</type>
    <actuator name="arm_motor_1">
      <mechanicalReduction>1</mechanicalReduction>
    </actuator>
    <joint name="arm_joint_1">
      <hardwareInterface>hardware_interface/EffortJointInterface</hardwareInterface>
    </joint>
  </transmission>
  <transmission name="arm_trans_2">
    <type>transmission_interface/SimpleTransmission</type>
    <actuator name="arm_motor_2">
      <mechanicalReduction>1</mechanicalReduction>
    </actuator>
    <joint name="arm_joint_2">
      <hardwareInterface>hardware_interface/EffortJointInterface</hardwareInterface>
    </joint>
  </transmission>
  <transmission name="arm_trans_3">
    <type>transmission_interface/SimpleTransmission</type>
    <actuator name="arm_motor_3">
      <mechanicalReduction>1</mechanicalReduction>
    </actuator>
    <joint name="arm_joint_3">
      <hardwareInterface>hardware_interface/EffortJointInterface</hardwareInterface>
    </joint>
  </transmission>
  <transmission name="arm_trans_4">
    <type>transmission_interface/SimpleTransmission</type>
    <actuator name="arm_motor_4">
      <mechanicalReduction>1</mechanicalReduction>
    </actuator>
    <joint name="arm_joint_4">
      <hardwareInterface>hardware_interface/EffortJointInterface</hardwareInterface>
    </joint>
  </transmission>
  <transmission name="arm_trans_5">
    <type>transmission_interface/SimpleTransmission</type>
    <actuator name="arm_motor_5">
      <mechanicalReduction>1</mechanicalReduction>
    </actuator>
    <joint name="arm_joint_5">
      <hardwareInterface>hardware_interface/EffortJointInterface</hardwareInterface>
    </joint>
  </transmission>
  <joint name="base_laser_front_hokuyo_urg04_laser_joint" type="fixed">
    <axis xyz="0 1 0"/>
    <origin rpy="3.141592653589793 0 0" xyz="0.3 0 -0.035"/>
    <parent link="base_link"/>
    <child link="base_laser_front_link"/>
  </joint>
  <link name="base_laser_front_link">
    <inertial>
      <mass value="0.16"/>
      <origin rpy="0 0 0" xyz="0 0 0"/>
      <inertia ixx="0.1" ixy="0" ixz="0" iyy="0.1" iyz="0" izz="0.1"/>
    </inertial>
    <visual>
      <origin rpy="0 0 0" xyz="0 0 0"/>
      <geometry>
        <mesh filename="package://youbot_description/meshes/sensors/hokuyo.dae"/>
      </geometry>
    </visual>
    <collision>
      <origin rpy="0 0 0" xyz="0 0 0"/>
      <geometry>
        <mesh filename="package://youbot_description/meshes/sensors/hokuyo_convex.dae"/>
      </geometry>
    </collision>
  </link>
  <gazebo reference="base_laser_front_link">
    <sensor name="base_laser_front" type="ray">
      <update_rate>10</update_rate>
      <pose>0 0 0 0 0 0</pose>
      <visualize>false</visualize>
      <ray>
        <scan>
          <horizontal>
            <samples>150</samples>
            <resolution>1.0</resolution>
            <min_angle>-1.57</min_angle>
            <max_angle>1.57</max_angle>
          </horizontal>
        </scan>
        <range>
          <min>0.05</min>
          <max>5.6</max>
          <resolution>0.36</resolution>
        </range>
      </ray>
      <plugin filename="libgazebo_ros_laser.so" name="gazebo_ros_base_laser_front_controller">
        <gaussianNoise>0.005</gaussianNoise>
        <updateRate>10</updateRate>
        <topicName>scan_front</topicName>
        <frameName>/base_laser_front_link</frameName>
      </plugin>
    </sensor>
  </gazebo>
  <joint name="base_laser_rear_hokuyo_urg04_laser_joint" type="fixed">
    <axis xyz="0 1 0"/>
    <origin rpy="3.141592653589793 0 3.141592653589793" xyz="-0.3 0.0 -0.035"/>
    <parent link="base_link"/>
    <child link="base_laser_rear_link"/>
  </joint>
  <link name="base_laser_rear_link">
    <inertial>
      <mass value="0.16"/>
      <origin rpy="0 0 0" xyz="0 0 0"/>
      <inertia ixx="0.1" ixy="0" ixz="0" iyy="0.1" iyz="0" izz="0.1"/>
    </inertial>
    <visual>
      <origin rpy="0 0 0" xyz="0 0 0"/>
      <geometry>
        <mesh filename="package://youbot_description/meshes/sensors/hokuyo.dae"/>
      </geometry>
    </visual>
    <collision>
      <origin rpy="0 0 0" xyz="0 0 0"/>
      <geometry>
        <mesh filename="package://youbot_description/meshes/sensors/hokuyo_convex.dae"/>
      </geometry>
    </collision>
  </link>
  <gazebo reference="base_laser_rear_link">
    <sensor name="base_laser_rear" type="ray">
      <update_rate>10</update_rate>
      <pose>0 0 0 0 0 0</pose>
      <visualize>false</visualize>
      <ray>
        <scan>
          <horizontal>
            <samples>150</samples>
            <resolution>1.0</resolution>
            <min_angle>-1.57</min_angle>
            <max_angle>1.57</max_angle>
          </horizontal>
        </scan>
        <range>
          <min>0.05</min>
          <max>5.6</max>
          <resolution>0.36</resolution>
        </range>
      </ray>
      <plugin filename="libgazebo_ros_laser.so" name="gazebo_ros_base_laser_rear_controller">
        <gaussianNoise>0.005</gaussianNoise>
        <updateRate>10</updateRate>
        <topicName>scan_rear</topicName>
        <frameName>/base_laser_rear_link</frameName>
      </plugin>
    </sensor>
  </gazebo>
  <joint name="gripper_motor_mount_joint" type="fixed">
    <origin rpy="0 0 0" xyz="0.003 0 0.0052"/>
    <parent link="arm_link_5"/>
    <child link="gripper_motor_mount_link"/>
  </joint>
  <joint name="gripper_static_grasp_link_joint" type="fixed">
    <origin rpy="0 0 0" xyz="0 0 0.11"/>
    <parent link="arm_link_5"/>
    <child link="gripper_static_grasp_link"/>
  </joint>
  <link name="gripper_static_grasp_link">
    </link>
  <!-- motor mount -->
  <link name="gripper_motor_mount_link">
    <inertial>
      <origin rpy="0 0 0" xyz="0 0 0"/>
      <mass value="0.038"/>
      <inertia ixx="0.01" ixy="0" ixz="0" iyy="0.01" iyz="0" izz="0.01"/>
    </inertial>
    <visual>
      <origin rpy="0 1.5707963267948966 0" xyz="0 0 0.0"/>
      <geometry>
        <mesh filename="package://mir_description/meshes/grippers/dynamixel/v3/dynamixel_intel_camera_combined.stl" scale="0.001 0.001 0.001"/>
      </geometry>
    </visual>
    <collision>
      <origin rpy="0 1.5707963267948966 0" xyz="0 0 -0.0"/>
      <geometry>
        <mesh filename="package://mir_description/meshes/grippers/dynamixel/v2/dynamixel_motor_mount_convex_hull.dae" scale="0.001 0.001 0.001"/>
      </geometry>
    </collision>
  </link>
  <joint name="gripper_motor_left_base_joint" type="fixed">
    <origin rpy="0 0 0" xyz="0.0 0.034 -0.009"/>
    <parent link="gripper_motor_mount_link"/>
    <child link="gripper_motor_left_base_link"/>
  </joint>
  <link name="gripper_motor_left_base_link">
    <inertial>
      <origin rpy="0 0 0" xyz="0 0 0"/>
      <mass value="0.054"/>
      <inertia ixx="0.01" ixy="0" ixz="0" iyy="0.01" iyz="0" izz="0.01"/>
    </inertial>
    <visual>
      <origin rpy="0 1.5707963267948966 0" xyz="0 0 0.03"/>
      <geometry>
        <mesh filename="package://mcr_description/meshes/motors/dynamixel_motor_ax-12a.dae" scale="0.001 0.001 0.001"/>
      </geometry>
    </visual>
    <collision>
      <origin rpy="0 1.5707963267948966 0" xyz="0 0 0.03"/>
      <geometry>
        <mesh filename="package://mcr_description/meshes/motors/dynamixel_motor_ax-12a_convex_hull.dae" scale="0.001 0.001 0.001"/>
      </geometry>
    </collision>
  </link>
  <joint name="gripper_motor_left_joint" type="revolute">
    <parent link="gripper_motor_left_base_link"/>
    <child link="gripper_motor_left_link"/>
    <origin rpy="0.065 0 3.141592653589793" xyz="0 0 0.03"/>
    <axis xyz="-1 0 0"/>
    <limit effort="1.5" lower="-2.6179938779914944" upper="2.6179938779914944" velocity="6.178465545"/>
  </joint>
  <link name="gripper_motor_left_link">
    <inertial>
      <origin rpy="0 0 0" xyz="0 0 0"/>
      <mass value="0.001"/>
      <inertia ixx="0.01" ixy="0" ixz="0" iyy="0.01" iyz="0" izz="0.01"/>
    </inertial>
  </link>
  <gazebo reference="gripper_motor_left_link">
    <turnGravityOff>false</turnGravityOff>
  </gazebo>
  <transmission name="gripper_motor_left_trans">
    <type>transmission_interface/SimpleTransmission</type>
    <actuator name="gripper_motor_left_motor">
      <mechanicalReduction>1</mechanicalReduction>
    </actuator>
    <joint name="gripper_motor_left_joint">
      <hardwareInterface>EffortJointInterface</hardwareInterface>
    </joint>
  </transmission>
  <joint name="gripper_motor_right_base_joint" type="fixed">
    <origin rpy="0 0 0" xyz="0.0 -0.034 -0.009"/>
    <parent link="gripper_motor_mount_link"/>
    <child link="gripper_motor_right_base_link"/>
  </joint>
  <link name="gripper_motor_right_base_link">
    <inertial>
      <origin rpy="0 0 0" xyz="0 0 0"/>
      <mass value="0.054"/>
      <inertia ixx="0.01" ixy="0" ixz="0" iyy="0.01" iyz="0" izz="0.01"/>
    </inertial>
    <visual>
      <origin rpy="0 1.5707963267948966 0" xyz="0 0 0.03"/>
      <geometry>
        <mesh filename="package://mcr_description/meshes/motors/dynamixel_motor_ax-12a.dae" scale="0.001 0.001 0.001"/>
      </geometry>
    </visual>
    <collision>
      <origin rpy="0 1.5707963267948966 0" xyz="0 0 0.03"/>
      <geometry>
        <mesh filename="package://mcr_description/meshes/motors/dynamixel_motor_ax-12a_convex_hull.dae" scale="0.001 0.001 0.001"/>
      </geometry>
    </collision>
  </link>
  <joint name="gripper_motor_right_joint" type="revolute">
    <parent link="gripper_motor_right_base_link"/>
    <child link="gripper_motor_right_link"/>
    <origin rpy="-0.065 0 3.141592653589793" xyz="0 0 0.03"/>
    <axis xyz="1 0 0"/>
    <limit effort="1.5" lower="-2.6179938779914944" upper="2.6179938779914944" velocity="6.178465545"/>
  </joint>
  <link name="gripper_motor_right_link">
    <inertial>
      <origin rpy="0 0 0" xyz="0 0 0"/>
      <mass value="0.001"/>
      <inertia ixx="0.01" ixy="0" ixz="0" iyy="0.01" iyz="0" izz="0.01"/>
    </inertial>
  </link>
  <gazebo reference="gripper_motor_right_link">
    <turnGravityOff>false</turnGravityOff>
  </gazebo>
  <transmission name="gripper_motor_right_trans">
    <type>transmission_interface/SimpleTransmission</type>
    <actuator name="gripper_motor_right_motor">
      <mechanicalReduction>1</mechanicalReduction>
    </actuator>
    <joint name="gripper_motor_right_joint">
      <hardwareInterface>EffortJointInterface</hardwareInterface>
    </joint>
  </transmission>
  <joint name="gripper_bracket_left_joint" type="fixed">
    <origin rpy="0 0 0" xyz="0 0 0"/>
    <parent link="gripper_motor_left_base_link"/>
    <child link="gripper_bracket_left_link"/>
  </joint>
  <link name="gripper_bracket_left_link">
    <inertial>
      <origin rpy="0 0 0" xyz="0 0 0"/>
      <mass value="0.011"/>
      <inertia ixx="0.01" ixy="0" ixz="0" iyy="0.01" iyz="0" izz="0.01"/>
    </inertial>
    <visual>
      <origin rpy="0 0 0" xyz="0 0 0"/>
      <geometry>
        <mesh filename="package://mcr_description/meshes/motors/dynamixel_bracket_fp04-f2.dae" scale="0.001 0.001 0.001"/>
      </geometry>
    </visual>
    <collision>
      <origin rpy="0 0 0" xyz="0 0 0"/>
      <geometry>
        <mesh filename="package://mcr_description/meshes/motors/dynamixel_bracket_fp04-f2_convex_hull.dae" scale="0.001 0.001 0.001"/>
      </geometry>
    </collision>
  </link>
  <joint name="gripper_bracket_right_joint" type="fixed">
    <origin rpy="0 0 0" xyz="0 0 0"/>
    <parent link="gripper_motor_right_base_link"/>
    <child link="gripper_bracket_right_link"/>
  </joint>
  <link name="gripper_bracket_right_link">
    <inertial>
      <origin rpy="0 0 0" xyz="0 0 0"/>
      <mass value="0.011"/>
      <inertia ixx="0.01" ixy="0" ixz="0" iyy="0.01" iyz="0" izz="0.01"/>
    </inertial>
    <visual>
      <origin rpy="0 0 0" xyz="0 0 0"/>
      <geometry>
        <mesh filename="package://mcr_description/meshes/motors/dynamixel_bracket_fp04-f2.dae" scale="0.001 0.001 0.001"/>
      </geometry>
    </visual>
    <collision>
      <origin rpy="0 0 0" xyz="0 0 0"/>
      <geometry>
        <mesh filename="package://mcr_description/meshes/motors/dynamixel_bracket_fp04-f2_convex_hull.dae" scale="0.001 0.001 0.001"/>
      </geometry>
    </collision>
  </link>
  <joint name="gripper_finger_mount_left_joint" type="fixed">
    <origin rpy="0 0 3.141592653589793" xyz="0.014 +0.0125 0.026"/>
    <parent link="gripper_bracket_left_link"/>
    <child link="gripper_finger_mount_left_link"/>
  </joint>
  <link name="gripper_finger_mount_left_link">
    <inertial>
      <origin rpy="0 0 0" xyz="0 0 0"/>
      <mass value="0.009"/>
      <inertia ixx="0.01" ixy="0" ixz="0" iyy="0.01" iyz="0" izz="0.01"/>
    </inertial>
    <visual>
      <origin rpy="1.5707963267948966 0 3.141592653589793" xyz="0 0 0"/>
      <geometry>
        <mesh filename="package://mir_description/meshes/grippers/dynamixel/v2/festo_finger_mount.dae" scale="0.001 0.001 0.001"/>
      </geometry>
    </visual>
    <collision>
      <origin rpy="1.5707963267948966 0 3.141592653589793" xyz="0 0 0"/>
      <geometry>
        <mesh filename="package://mir_description/meshes/grippers/dynamixel/v2/festo_finger_mount_convex_hull.dae" scale="0.001 0.001 0.001"/>
      </geometry>
    </collision>
  </link>
  <joint name="gripper_finger_mount_right_joint" type="fixed">
    <origin rpy="0 0 0" xyz="-0.014 -0.0125 0.026"/>
    <parent link="gripper_bracket_right_link"/>
    <child link="gripper_finger_mount_right_link"/>
  </joint>
  <link name="gripper_finger_mount_right_link">
    <inertial>
      <origin rpy="0 0 0" xyz="0 0 0"/>
      <mass value="0.009"/>
      <inertia ixx="0.01" ixy="0" ixz="0" iyy="0.01" iyz="0" izz="0.01"/>
    </inertial>
    <visual>
      <origin rpy="1.5707963267948966 0 3.141592653589793" xyz="0 0 0"/>
      <geometry>
        <mesh filename="package://mir_description/meshes/grippers/dynamixel/v2/festo_finger_mount.dae" scale="0.001 0.001 0.001"/>
      </geometry>
    </visual>
    <collision>
      <origin rpy="1.5707963267948966 0 3.141592653589793" xyz="0 0 0"/>
      <geometry>
        <mesh filename="package://mir_description/meshes/grippers/dynamixel/v2/festo_finger_mount_convex_hull.dae" scale="0.001 0.001 0.001"/>
      </geometry>
    </collision>
  </link>
  <joint name="gripper_finger_left_joint" type="fixed">
    <origin rpy="0 0 0" xyz="0.004 0 0.0045"/>
    <parent link="gripper_finger_mount_left_link"/>
    <child link="gripper_finger_left_link"/>
  </joint>
  <link name="gripper_finger_left_link">
    <inertial>
      <origin rpy="0 0 0" xyz="0 0 0"/>
      <mass value="0.015"/>
      <inertia ixx="0.01" ixy="0" ixz="0" iyy="0.01" iyz="0" izz="0.01"/>
    </inertial>
    <visual>
      <origin rpy="1.5707963267948966 0 1.5707963267948966" xyz="0 0 0"/>
      <geometry>
        <mesh filename="package://mcr_description/meshes/fingers/festo_finger_dhas-gf-shm.dae" scale="0.001 0.001 0.001"/>
      </geometry>
    </visual>
    <collision>
      <origin rpy="1.5707963267948966 0 1.5707963267948966" xyz="0 0 0"/>
      <geometry>
        <mesh filename="package://mcr_description/meshes/fingers/festo_finger_dhas-gf-shm_convex_hull.dae" scale="0.001 0.001 0.001"/>
      </geometry>
    </collision>
  </link>
  <joint name="gripper_finger_right_joint" type="fixed">
    <origin rpy="0 0 0" xyz="0.004 0 0.0045"/>
    <parent link="gripper_finger_mount_right_link"/>
    <child link="gripper_finger_right_link"/>
  </joint>
  <link name="gripper_finger_right_link">
    <inertial>
      <origin rpy="0 0 0" xyz="0 0 0"/>
      <mass value="0.015"/>
      <inertia ixx="0.01" ixy="0" ixz="0" iyy="0.01" iyz="0" izz="0.01"/>
    </inertial>
    <visual>
      <origin rpy="1.5707963267948966 0 1.5707963267948966" xyz="0 0 0"/>
      <geometry>
        <mesh filename="package://mcr_description/meshes/fingers/festo_finger_dhas-gf-shm.dae" scale="0.001 0.001 0.001"/>
      </geometry>
    </visual>
    <collision>
      <origin rpy="1.5707963267948966 0 1.5707963267948966" xyz="0 0 0"/>
      <geometry>
        <mesh filename="package://mcr_description/meshes/fingers/festo_finger_dhas-gf-shm_convex_hull.dae" scale="0.001 0.001 0.001"/>
      </geometry>
    </collision>
  </link>
  <!-- camera mount for Intel RealSense F200 -->
  <!--xacro:asus_xtion_camera_mount  name="camera_mount" parent="gripper_motor_mount_link">
      <origin xyz="0.035 -0.00 0.0" rpy="0 0.025 ${M_PI/2} " />
  </xacro:asus_xtion_camera_mount-->
  <!-- 3D camera on arm -->
  <!-- xacro:intel_realsense_f200_camera name="arm_cam3d" parent="camera_mount_link">
    <origin xyz="-0.05 -0.01 0.03" rpy="0.0 -${M_PI/2 - 0.03} 0.0" />
  </xacro:intel_realsense_f200_camera -->
  <material name="tower_cam3d_aluminum">
    <color rgba="0.5 0.5 0.5 1"/>
  </material>
  <!-- camera body, with origin at bottom screw mount -->
  <joint name="tower_cam3d_camera_joint" type="fixed">
    <origin rpy="-0.055 1.16 0.0" xyz="0.298 -0.039 0.795"/>
    <parent link="base_link"/>
    <child link="tower_cam3d_camera_link"/>
  </joint>
  <link name="tower_cam3d_camera_link">
    <visual>
      <origin rpy="1.5707963267948966 0 1.5707963267948966" xyz="0.0149 0.0 0.0125"/>
      <geometry>
        <mesh filename="package://mcr_description/meshes/sensors/realsense_d435.dae"/>
      </geometry>
      <material name="tower_cam3d_aluminum"/>
    </visual>
    <collision>
      <origin rpy="0 0 0" xyz="0.0 0.0 0.0125"/>
      <geometry>
        <box size="0.02505 0.09 0.025"/>
      </geometry>
    </collision>
    <inertial>
      <!-- The following are not reliable values, and should not be used for modeling -->
      <mass value="0.564"/>
      <origin xyz="0 0 0"/>
      <inertia ixx="0.003881243" ixy="0.0" ixz="0.0" iyy="0.000498940" iyz="0.0" izz="0.003879257"/>
    </inertial>
  </link>
  <!-- camera depth joints and links -->
  <joint name="tower_cam3d_camera_depth_joint" type="fixed">
    <origin rpy="0 0 0" xyz="0.0149 0.0175 0.0125"/>
    <parent link="tower_cam3d_camera_link"/>
    <child link="tower_cam3d_camera_depth_frame"/>
  </joint>
  <link name="tower_cam3d_camera_depth_frame"/>
  <joint name="tower_cam3d_camera_depth_optical_joint" type="fixed">
    <origin rpy="-1.5707963267948966 0 -1.5707963267948966" xyz="0 0 0"/>
    <parent link="tower_cam3d_camera_depth_frame"/>
    <child link="tower_cam3d_camera_depth_optical_frame"/>
  </joint>
  <link name="tower_cam3d_camera_depth_optical_frame"/>
  <!-- camera left IR joints and links -->
  <joint name="tower_cam3d_camera_left_ir_joint" type="fixed">
    <origin rpy="0 0 0" xyz="0 0.0 0"/>
    <parent link="tower_cam3d_camera_depth_frame"/>
    <child link="tower_cam3d_camera_left_ir_frame"/>
  </joint>
  <link name="tower_cam3d_camera_left_ir_frame"/>
  <joint name="tower_cam3d_camera_left_ir_optical_joint" type="fixed">
    <origin rpy="-1.5707963267948966 0 -1.5707963267948966" xyz="0 0 0"/>
    <parent link="tower_cam3d_camera_left_ir_frame"/>
    <child link="tower_cam3d_camera_left_ir_optical_frame"/>
  </joint>
  <link name="tower_cam3d_camera_left_ir_optical_frame"/>
  <!-- camera right IR joints and links -->
  <joint name="tower_cam3d_camera_right_ir_joint" type="fixed">
    <origin rpy="0 0 0" xyz="0 -0.05 0"/>
    <parent link="tower_cam3d_camera_depth_frame"/>
    <child link="tower_cam3d_camera_right_ir_frame"/>
  </joint>
  <link name="tower_cam3d_camera_right_ir_frame"/>
  <joint name="tower_cam3d_camera_right_ir_optical_joint" type="fixed">
    <origin rpy="-1.5707963267948966 0 -1.5707963267948966" xyz="0 0 0"/>
    <parent link="tower_cam3d_camera_right_ir_frame"/>
    <child link="tower_cam3d_camera_right_ir_optical_frame"/>
  </joint>
  <link name="tower_cam3d_camera_right_ir_optical_frame"/>
  <!-- camera color joints and links -->
  <joint name="tower_cam3d_camera_color_joint" type="fixed">
    <origin rpy="0 0 0" xyz="0 0.015 0"/>
    <parent link="tower_cam3d_camera_depth_frame"/>
    <child link="tower_cam3d_camera_color_frame"/>
  </joint>
  <link name="tower_cam3d_camera_color_frame"/>
  <joint name="tower_cam3d_camera_color_optical_joint" type="fixed">
    <origin rpy="-1.5707963267948966 0 -1.5707963267948966" xyz="0 0 0"/>
    <parent link="tower_cam3d_camera_color_frame"/>
    <child link="tower_cam3d_camera_color_optical_frame"/>
  </joint>
  <link name="tower_cam3d_camera_color_optical_frame"/>
  <gazebo reference="tower_cam3d_camera_link">
    <sensor name="tower_cam3d_depth_sensor" type="depth">
      <update_rate>20.0</update_rate>
      <camera name="tower_cam3d_camera">
        <horizontal_fov>1.21</horizontal_fov>
        <image>
          <width>640</width>
          <height>480</height>
          <format>B8G8R8</format>
        </image>
        <clip>
          <near>0.13</near>
          <far>30.0</far>
        </clip>
        <noise>
          <type>gaussian</type>
          <mean>0.0</mean>
          <stddev>0.007</stddev>
        </noise>
      </camera>
      <plugin filename="libgazebo_ros_openni_kinect.so" name="tower_cam3d_realsense_d435_plugin">
        <baseline>0.2</baseline>
        <alwaysOn>true</alwaysOn>
        <updateRate>0.0</updateRate>
        <cameraName>tower_cam3d_ir</cameraName>
        <imageTopicName>/tower_cam3d/rgb/image_raw</imageTopicName>
        <cameraInfoTopicName>/tower_cam3d/rgb/camera_info</cameraInfoTopicName>
        <depthImageTopicName>/tower_cam3d/depth/image_raw</depthImageTopicName>
        <depthImageInfoTopicName>/tower_cam3d/depth/camera_info</depthImageInfoTopicName>
        <pointCloudTopicName>/tower_cam3d/depth_registered/points</pointCloudTopicName>
        <frameName>/tower_cam3d_camera_depth_optical_frame</frameName>
        <pointCloudCutoff>0.105</pointCloudCutoff>
        <pointCloudCutoffMax>10.0</pointCloudCutoffMax>
        <distortionK1>0.00000001</distortionK1>
        <distortionK2>0.00000001</distortionK2>
        <distortionK3>0.00000001</distortionK3>
        <distortionT1>0.00000001</distortionT1>
        <distortionT2>0.00000001</distortionT2>
        <CxPrime>0</CxPrime>
        <Cx>0</Cx>
        <Cy>0</Cy>
        <focalLength>0</focalLength>
        <hackBaseline>0</hackBaseline>
      </plugin>
    </sensor>
  </gazebo>
  <material name="arm_cam3d_aluminum">
    <color rgba="0.5 0.5 0.5 1"/>
  </material>
  <!-- camera body, with origin at bottom screw mount -->
  <joint name="arm_cam3d_camera_joint" type="fixed">
    <origin rpy="0.0 -1.5707963267948966 -1.5707963267948966" xyz="-0.005 -0.008 0.009"/>
    <parent link="arm_link_5"/>
    <child link="arm_cam3d_camera_link"/>
  </joint>
  <link name="arm_cam3d_camera_link">
    <visual>
      <origin rpy="1.5707963267948966 0 1.5707963267948966" xyz="0.0149 0.0 0.0125"/>
      <geometry>
        <mesh filename="package://mcr_description/meshes/sensors/realsense_d435.dae"/>
      </geometry>
      <material name="arm_cam3d_aluminum"/>
    </visual>
    <collision>
      <origin rpy="0 0 0" xyz="0.0 0.0 0.0125"/>
      <geometry>
        <box size="0.02505 0.09 0.025"/>
      </geometry>
    </collision>
    <inertial>
      <!-- The following are not reliable values, and should not be used for modeling -->
      <mass value="0.564"/>
      <origin xyz="0 0 0"/>
      <inertia ixx="0.003881243" ixy="0.0" ixz="0.0" iyy="0.000498940" iyz="0.0" izz="0.003879257"/>
    </inertial>
  </link>
  <!-- camera depth joints and links -->
  <joint name="arm_cam3d_camera_depth_joint" type="fixed">
    <origin rpy="0 0 0" xyz="0.0149 0.0175 0.0125"/>
    <parent link="arm_cam3d_camera_link"/>
    <child link="arm_cam3d_camera_depth_frame"/>
  </joint>
  <link name="arm_cam3d_camera_depth_frame"/>
  <joint name="arm_cam3d_camera_depth_optical_joint" type="fixed">
    <origin rpy="-1.5707963267948966 0 -1.5707963267948966" xyz="0 0 0"/>
    <parent link="arm_cam3d_camera_depth_frame"/>
    <child link="arm_cam3d_camera_depth_optical_frame"/>
  </joint>
  <link name="arm_cam3d_camera_depth_optical_frame"/>
  <!-- camera left IR joints and links -->
  <joint name="arm_cam3d_camera_left_ir_joint" type="fixed">
    <origin rpy="0 0 0" xyz="0 0.0 0"/>
    <parent link="arm_cam3d_camera_depth_frame"/>
    <child link="arm_cam3d_camera_left_ir_frame"/>
  </joint>
  <link name="arm_cam3d_camera_left_ir_frame"/>
  <joint name="arm_cam3d_camera_left_ir_optical_joint" type="fixed">
    <origin rpy="-1.5707963267948966 0 -1.5707963267948966" xyz="0 0 0"/>
    <parent link="arm_cam3d_camera_left_ir_frame"/>
    <child link="arm_cam3d_camera_left_ir_optical_frame"/>
  </joint>
  <link name="arm_cam3d_camera_left_ir_optical_frame"/>
  <!-- camera right IR joints and links -->
  <joint name="arm_cam3d_camera_right_ir_joint" type="fixed">
    <origin rpy="0 0 0" xyz="0 -0.05 0"/>
    <parent link="arm_cam3d_camera_depth_frame"/>
    <child link="arm_cam3d_camera_right_ir_frame"/>
  </joint>
  <link name="arm_cam3d_camera_right_ir_frame"/>
  <joint name="arm_cam3d_camera_right_ir_optical_joint" type="fixed">
    <origin rpy="-1.5707963267948966 0 -1.5707963267948966" xyz="0 0 0"/>
    <parent link="arm_cam3d_camera_right_ir_frame"/>
    <child link="arm_cam3d_camera_right_ir_optical_frame"/>
  </joint>
  <link name="arm_cam3d_camera_right_ir_optical_frame"/>
  <!-- camera color joints and links -->
  <joint name="arm_cam3d_camera_color_joint" type="fixed">
    <origin rpy="0 0 0" xyz="0 0.015 0"/>
    <parent link="arm_cam3d_camera_depth_frame"/>
    <child link="arm_cam3d_camera_color_frame"/>
  </joint>
  <link name="arm_cam3d_camera_color_frame"/>
  <joint name="arm_cam3d_camera_color_optical_joint" type="fixed">
    <origin rpy="-1.5707963267948966 0 -1.5707963267948966" xyz="0 0 0"/>
    <parent link="arm_cam3d_camera_color_frame"/>
    <child link="arm_cam3d_camera_color_optical_frame"/>
  </joint>
  <link name="arm_cam3d_camera_color_optical_frame"/>
  <gazebo reference="arm_cam3d_camera_link">
    <sensor name="arm_cam3d_depth_sensor" type="depth">
      <update_rate>20.0</update_rate>
      <camera name="arm_cam3d_camera">
        <horizontal_fov>1.21</horizontal_fov>
        <image>
          <width>640</width>
          <height>480</height>
          <format>B8G8R8</format>
        </image>
        <clip>
          <near>0.13</near>
          <far>30.0</far>
        </clip>
        <noise>
          <type>gaussian</type>
          <mean>0.0</mean>
          <stddev>0.007</stddev>
        </noise>
      </camera>
      <plugin filename="libgazebo_ros_openni_kinect.so" name="arm_cam3d_realsense_d435_plugin">
        <baseline>0.2</baseline>
        <alwaysOn>true</alwaysOn>
        <updateRate>0.0</updateRate>
        <cameraName>arm_cam3d_ir</cameraName>
        <imageTopicName>/arm_cam3d/rgb/image_raw</imageTopicName>
        <cameraInfoTopicName>/arm_cam3d/rgb/camera_info</cameraInfoTopicName>
        <depthImageTopicName>/arm_cam3d/depth/image_raw</depthImageTopicName>
        <depthImageInfoTopicName>/arm_cam3d/depth/camera_info</depthImageInfoTopicName>
        <pointCloudTopicName>/arm_cam3d/depth_registered/points</pointCloudTopicName>
        <frameName>/arm_cam3d_camera_depth_optical_frame</frameName>
        <pointCloudCutoff>0.105</pointCloudCutoff>
        <pointCloudCutoffMax>10.0</pointCloudCutoffMax>
        <distortionK1>0.00000001</distortionK1>
        <distortionK2>0.00000001</distortionK2>
        <distortionK3>0.00000001</distortionK3>
        <distortionT1>0.00000001</distortionT1>
        <distortionT2>0.00000001</distortionT2>
        <CxPrime>0</CxPrime>
        <Cx>0</Cx>
        <Cy>0</Cy>
        <focalLength>0</focalLength>
        <hackBaseline>0</hackBaseline>
      </plugin>
    </sensor>
  </gazebo>
  <joint name="fixed_camera_joint" type="fixed">
    <origin rpy="-1.5707963267948966 0 -1.5707963267948966" xyz="0.0149 0.0325 0.0125"/>
    <parent link="arm_cam3d_camera_link"/>
    <child link="fixed_camera_link"/>
  </joint>
  <!-- we create a fixed link from arm_cam3d_camera_link to
        arm_cam3d_camera_color_optical_frame. See commit: https://github.com/b-it-bots/mas_industrial_robotics/commit/f6e3bfa997b430278adbf4b552a285ce43e47936 -->
  <!-- this also means you have to edit the source frame of the input
             pointcloud before transforming it. see commit: https://github.com/b-it-bots/mas_industrial_robotics/commit/f4dd2f3124779fbedd28beb636e9ca7019baa9cf -->
  <link name="fixed_camera_link">
    <visual>
      <geometry>
        <box size="0.0000001 0.000001 0.000001"/>
      </geometry>
    </visual>
    <collision>
      <geometry>
        <box size="0.0000001 0.000001 0.000001"/>
      </geometry>
    </collision>
  </link>
</robot>
